Workbook

Sheet 预算总表
A1: 全屋装修预算清单（原木风 · 保定中档口径）
A2: 编制日期：2026-09-22 建筑面积约232㎡（套内） 价格为参考区间，最终以实际报价为准
A3: 楼层 | B3: 房间 | C3: 科目 | D3: 项目说明 | E3: 单位 | F3: 工程量 | G3: 单价低(元) | H3: 单价高(元) | I3: 合价低(元) | J3: 合价高(元) | K3: 备注
A4: ▼ B1 车库层
A5: B1 车库层 | B5: 车库 | C5: 拆改 | D5: 墙面基层清理/界面剂 | E5: ㎡ | F5: 116 | G5: 4 | H5: 8 | I5: =ROUND(F5*G5,0) | J5: =ROUND(F5*H5,0)
A6: B1 车库层 | B6: 车库 | C6: 水电 | D6: 照明及充电桩线路（人工+辅材） | E6: 项 | F6: 1 | G6: 1200 | H6: 2800 | I6: =ROUND(F6*G6,0) | J6: =ROUND(F6*H6,0)
A7: B1 车库层 | B7: 车库 | C7: 泥瓦 | D7: 地面找平+耐磨地坪漆 | E7: ㎡ | F7: 27 | G7: 45 | H7: 85 | I7: =ROUND(F7*G7,0) | J7: =ROUND(F7*H7,0)
A8: B1 车库层 | B8: 车库 | C8: 泥瓦 | D8: 排水沟/集水井（含盖板） | E8: 项 | F8: 1 | G8: 800 | H8: 1800 | I8: =ROUND(F8*G8,0) | J8: =ROUND(F8*H8,0)
A9: B1 车库层 | B9: 车库 | C9: 油漆 | D9: 墙面/顶面防霉乳胶漆（通高约5.8m） | E9: ㎡ | F9: 143 | G9: 28 | H9: 45 | I9: =ROUND(F9*G9,0) | J9: =ROUND(F9*H9,0)
A10: B1 车库层 | B10: 车库 | C10: 主材安装 | D10: 车库卷帘门（含电机安装） | E10: 樘 | F10: 1 | G10: 2500 | H10: 6000 | I10: =ROUND(F10*G10,0) | J10: =ROUND(F10*H10,0)
A11: B1 车库层 | B11: 工具间 | C11: 水电 | D11: 照明/插座线路（人工+辅材） | E11: 项 | F11: 1 | G11: 800 | H11: 1800 | I11: =ROUND(F11*G11,0) | J11: =ROUND(F11*H11,0)
A12: B1 车库层 | B12: 工具间 | C12: 泥瓦 | D12: 地面找平+地坪漆 | E12: ㎡ | F12: 18 | G12: 45 | H12: 85 | I12: =ROUND(F12*G12,0) | J12: =ROUND(F12*H12,0)
A13: B1 车库层 | B13: 工具间 | C13: 油漆 | D13: 墙顶防霉乳胶漆（通高） | E13: ㎡ | F13: 122 | G13: 28 | H13: 45 | I13: =ROUND(F13*G13,0) | J13: =ROUND(F13*H13,0)
A14: B1 车库层 | B14: 工具间 | C14: 木工 | D14: 简易工作台（现场制作） | E14: 项 | F14: 1 | G14: 600 | H14: 1500 | I14: =ROUND(F14*G14,0) | J14: =ROUND(F14*H14,0)
A15: B1 车库层 | B15: 储藏/设备间 | C15: 水电 | D15: 照明/插座线路（人工+辅材） | E15: 项 | F15: 1 | G15: 800 | H15: 1800 | I15: =ROUND(F15*G15,0) | J15: =ROUND(F15*H15,0)
A16: B1 车库层 | B16: 储藏/设备间 | C16: 泥瓦 | D16: 地面找平+地坪漆 | E16: ㎡ | F16: 19.8 | G16: 45 | H16: 85 | I16: =ROUND(F16*G16,0) | J16: =ROUND(F16*H16,0)
... A19: B1 车库层 | B19: 楼梯/公共 | C19: 油漆 | D19: 楼梯间墙顶乳胶漆 | E19: ㎡ | F19: 80 | G19: 28 | H19: 45 | I19: =ROUND(F19*G19,0) | J19: =ROUND(F19*H19,0)
A20: ▼ F1 一层
A21: F1 一层 | B21: 客厅 | C21: 拆改 | D21: 铲墙皮/界面处理 | E21: ㎡ | F21: 51 | G21: 7 | H21: 16 | I21: =ROUND(F21*G21,0) | J21: =ROUND(F21*H21,0)
A22: F1 一层 | B22: 客厅 | C22: 水电 | D22: 强弱电/插座点位（人工+辅材） | E22: ㎡ | F22: 23.2 | G22: 80 | H22: 120 | I22: =ROUND(F22*G22,0) | J22: =ROUND(F22*H22,0)
A23: F1 一层 | B23: 客厅 | C23: 泥瓦 | D23: 地面找平 | E23: ㎡ | F23: 23.2 | G23: 25 | H23: 40 | I23: =ROUND(F23*G23,0) | J23: =ROUND(F23*H23,0)
A24: F1 一层 | B24: 客厅 | C24: 木工 | D24: 石膏板平顶+窗帘盒 | E24: ㎡ | F24: 23.2 | G24: 100 | H24: 180 | I24: =ROUND(F24*G24,0) | J24: =ROUND(F24*H24,0)
A25: F1 一层 | B25: 客厅 | C25: 油漆 | D25: 墙面腻子+乳胶漆 | E25: ㎡ | F25: 51 | G25: 30 | H25: 45 | I25: =ROUND(F25*G25,0) | J25: =ROUND(F25*H25,0)
A26: F1 一层 | B26: 客厅 | C26: 主材安装 | D26: 多层实木地板（原木色，含安装） | E26: ㎡ | F26: 24.4 | G26: 260 | H26: 450 | I26: =ROUND(F26*G26,0) | J26: =ROUND(F26*H26,0)
A27: F1 一层 | B27: 客厅 | C27: 主材安装 | D27: 窗台石/小五金 | E27: 项 | F27: 1 | G27: 600 | H27: 1400 | I27: =ROUND(F27*G27,0) | J27: =ROUND(F27*H27,0)
A28: F1 一层 | B28: 餐厅 | C28: 拆改 | D28: 铲墙皮/界面处理 | E28: ㎡ | F28: 41 | G28: 7 | H28: 16 | I28: =ROUND(F28*G28,0) | J28: =ROUND(F28*H28,0)
A29: F1 一层 | B29: 餐厅 | C29: 水电 | D29: 强弱电/插座点位（人工+辅材） | E29: ㎡ | F29: 15 | G29: 80 | H29: 120 | I29: =ROUND(F29*G29,0) | J29: =ROUND(F29*H29,0)
A30: F1 一层 | B30: 餐厅 | C30: 泥瓦 | D30: 地面找平 | E30: ㎡ | F30: 15 | G30: 25 | H30: 40 | I30: =ROUND(F30*G30,0) | J30: =ROUND(F30*H30,0)
A31: F1 一层 | B31: 餐厅 | C31: 木工 | D31: 石膏板平顶+窗帘盒 | E31: ㎡ | F31: 15 | G31: 100 | H31: 180 | I31: =ROUND(F31*G31,0) | J31: =ROUND(F31*H31,0)
A32: F1 一层 | B32: 餐厅 | C32: 油漆 | D32: 墙面腻子+乳胶漆 | E32: ㎡ | F32: 41 | G32: 30 | H32: 45 | I32: =ROUND(F32*G32,0) | J32: =ROUND(F32*H32,0)
... A62: F1 一层 | B62: 入户/公共 | C62: 主材安装 | D62: 入户钢木大门（含门套，如更换） | E62: 樘 | F62: 1 | G62: 2500 | H62: 6000 | I62: =ROUND(F62*G62,0) | J62: =ROUND(F62*H62,0)
A63: ▼ F2 二层
A64: F2 二层 | B64: 西北卧 | C64: 拆改 | D64: 铲墙皮/界面处理 | E64: ㎡ | F64: 26 | G64: 7 | H64: 16 | I64: =ROUND(F64*G64,0) | J64: =ROUND(F64*H64,0)
A65: F2 二层 | B65: 西北卧 | C65: 水电 | D65: 强弱电/点位（人工+辅材） | E65: ㎡ | F65: 6.8 | G65: 80 | H65: 120 | I65: =ROUND(F65*G65,0) | J65: =ROUND(F65*H65,0)
A66: F2 二层 | B66: 西北卧 | C66: 泥瓦 | D66: 地面找平 | E66: ㎡ | F66: 6.8 | G66: 25 | H66: 40 | I66: =ROUND(F66*G66,0) | J66: =ROUND(F66*H66,0)
A67: F2 二层 | B67: 西北卧 | C67: 木工 | D67: 石膏顶角线/窗帘盒 | E67: m | F67: 10.5 | G67: 15 | H67: 28 | I67: =ROUND(F67*G67,0) | J67: =ROUND(F67*H67,0)
A68: F2 二层 | B68: 西北卧 | C68: 油漆 | D68: 墙面腻子+乳胶漆 | E68: ㎡ | F68: 26 | G68: 30 | H68: 45 | I68: =ROUND(F68*G68,0) | J68: =ROUND(F68*H68,0)
A69: F2 二层 | B69: 西北卧 | C69: 主材安装 | D69: 多层实木地板（原木色，含安装） | E69: ㎡ | F69: 7.1 | G69: 260 | H69: 450 | I69: =ROUND(F69*G69,0) | J69: =ROUND(F69*H69,0)
A70: F2 二层 | B70: 西北卧 | C70: 主材安装 | D70: 实木复合门（含套锁五金） | E70: 樘 | F70: 1 | G70: 1300 | H70: 2200 | I70: =ROUND(F70*G70,0) | J70: =ROUND(F70*H70,0)
A71: F2 二层 | B71: 西南卧 | C71: 拆改 | D71: 铲墙皮/界面处理 | E71: ㎡ | F71: 34 | G71: 7 | H71: 16 | I71: =ROUND(F71*G71,0) | J71: =ROUND(F71*H71,0)
...

Sheet 汇总
A1: 预算汇总（数据自动取自“预算总表”）
A3: 楼层 | B3: 合价低(元) | C3: 合价高(元) | D3: 占比(按中值)
A4: B1 车库层 | B4: =SUMIF('预算总表'!A:A,A4,'预算总表'!I:I) | C4: =SUMIF('预算总表'!A:A,A4,'预算总表'!J:J) | D4: =IFERROR((B4+C4)/(B$9+C$9),0)
A5: F1 一层 | B5: =SUMIF('预算总表'!A:A,A5,'预算总表'!I:I) | C5: =SUMIF('预算总表'!A:A,A5,'预算总表'!J:J) | D5: =IFERROR((B5+C5)/(B$9+C$9),0)
A6: F2 二层 | B6: =SUMIF('预算总表'!A:A,A6,'预算总表'!I:I) | C6: =SUMIF('预算总表'!A:A,A6,'预算总表'!J:J) | D6: =IFERROR((B6+C6)/(B$9+C$9),0)
A7: F3 三层 | B7: =SUMIF('预算总表'!A:A,A7,'预算总表'!I:I) | C7: =SUMIF('预算总表'!A:A,A7,'预算总表'!J:J) | D7: =IFERROR((B7+C7)/(B$9+C$9),0)
A8: 全屋 | B8: =SUMIF('预算总表'!A:A,A8,'预算总表'!I:I) | C8: =SUMIF('预算总表'!A:A,A8,'预算总表'!J:J) | D8: =IFERROR((B8+C8)/(B$9+C$9),0)
A9: 合计 | B9: =SUM(B4:B8) | C9: =SUM(C4:C8)
A11: 科目 | B11: 合价低(元) | C11: 合价高(元) | D11: 占比(按中值)
A12: 拆改 | B12: =SUMIF('预算总表'!C:C,A12,'预算总表'!I:I) | C12: =SUMIF('预算总表'!C:C,A12,'预算总表'!J:J) | D12: =IFERROR((B12+C12)/(B$19+C$19),0)
A13: 水电 | B13: =SUMIF('预算总表'!C:C,A13,'预算总表'!I:I) | C13: =SUMIF('预算总表'!C:C,A13,'预算总表'!J:J) | D13: =IFERROR((B13+C13)/(B$19+C$19),0)
A14: 泥瓦 | B14: =SUMIF('预算总表'!C:C,A14,'预算总表'!I:I) | C14: =SUMIF('预算总表'!C:C,A14,'预算总表'!J:J) | D14: =IFERROR((B14+C14)/(B$19+C$19),0)
A15: 木工 | B15: =SUMIF('预算总表'!C:C,A15,'预算总表'!I:I) | C15: =SUMIF('预算总表'!C:C,A15,'预算总表'!J:J) | D15: =IFERROR((B15+C15)/(B$19+C$19),0)
A16: 油漆 | B16: =SUMIF('预算总表'!C:C,A16,'预算总表'!I:I) | C16: =SUMIF('预算总表'!C:C,A16,'预算总表'!J:J) | D16: =IFERROR((B16+C16)/(B$19+C$19),0)
A17: 主材安装 | B17: =SUMIF('预算总表'!C:C,A17,'预算总表'!I:I) | C17: =SUMIF('预算总表'!C:C,A17,'预算总表'!J:J) | D17: =IFERROR((B17+C17)/(B$19+C$19),0)
A18: 其他 | B18: =SUMIF('预算总表'!C:C,A18,'预算总表'!I:I) | C18: =SUMIF('预算总表'!C:C,A18,'预算总表'!J:J) | D18: =IFERROR((B18+C18)/(B$19+C$19),0)
A19: 合计 | B19: =SUM(B12:B18) | C19: =SUM(C12:C18)
A21: 项目 | B21: 金额低(元) | C21: 金额高(元) | D21: 折合每㎡(元)
A22: 基装合计（拆改/水电/泥瓦/木工/油漆/其他） | B22: =SUM(B12:B16)+B18 | C22: =SUM(C12:C16)+C18 | D22: =ROUND((B22+C22)/2/232,0)
A23: 主材合计（主材安装） | B23: =B17 | C23: =C17 | D23: =ROUND((B23+C23)/2/232,0)
A24: 工程合计 | B24: ='预算总表'!I158 | C24: ='预算总表'!J158 | D24: =ROUND((B24+C24)/2/232,0)
A25: 暂列金（8%–10%） | B25: ='预算总表'!I159 | C25: ='预算总表'!J159 | D25: =ROUND((B25+C25)/2/232,0)
A26: 预计总投入区间 | B26: ='预算总表'!I160 | C26: ='预算总表'!J160 | D26: =ROUND((B26+C26)/2/232,0)

Sheet 说明
A1: 预算编制说明
A2: 一、编制依据
A3: 1. 依据设计师施工图：别墅一层平面图、二层平面图、1-1剖面图（图签 L29# 1-1剖面图 1:200）。
A4: 2. 风格口径：原木风（多层实木地板、原木/实木复合橱柜与定制柜、实木复合门、木饰面），中档定位。
A5: 3. 价格口径：2026年9月河北保定市场参考区间，人工参考土巴兔保定价格指南及2026年工程人公开报价，
A6: 主材参考土巴兔2026地板价格指南、淘宝/1688在售材料价；仅作预算参考，正式签约前请至少取得3家报价。
A7: 二、工程量口径
A8: 1. 原始平面图未标注数字尺寸链，房间尺寸按剖面图轴网（4500+3000+3300=10800mm）反推，精度约±100mm。
A9: 2. 面积为房间净面积；地板、瓷砖工程量已含约5%损耗；墙面面积按周长×层高并扣除门窗洞口估算。
A10: 3. B1车库层（-6.000）为通高空间，顶板即一层±0.000地面，墙顶面按通高约5.8m计；若后期加设夹层，费用另计。
A11: 4. F3三层布局（主卧/主卫/露台）系按1-1剖面图推断；露台地面标高7.200，女儿墙呈7.6/8.0/8.6阶梯状。
A12: 5. 车库北侧下沉通道及坡道为示意做法（图纸未画车行路径），坡道与挡墙土建费用未包含在本预算内。
... A24: 4. 原木风注意木材含水率与环保等级（建议ENF/E0级），保定冬季干燥供暖，实木类需预留伸缩缝。
